═══════════════════ Testando o código com os casos de teste ════════════════════
=> Códigos:[exception.cpp] Testes:[cases.tio(01)] [ϵ]
(ϵ erro_execução__)[00] GR:100 cases.tio ()
╭──────────────────────────────────────────────────────────────────────────────╮
│                 (ϵ erro_execução__)[00] GR:100 cases.tio ()                  │
├────────────────────────────────── INSERIDO ──────────────────────────────────┤
│ 1                                                                            │
│ 2                                                                            │
│ 3                                                                            │
│ 4                                                                            │
├────────────────────────────────── ESPERADO ──────────────────────────────────┤
│ 1                                                                            │
│ 2                                                                            │
│ 3                                                                            │
│ 4                                                                            │
│                                                                              │
├────────────────────────────────── RECEBIDO ──────────────────────────────────┤
│ 1                                                                            │
│ 2                                                                            │
│ terminate called after throwing an instance of 'std::runtime_error'          │
│   what():  pane no sistema                                                   │
│ fail: runtime exception                                                      │
╰──────────────────────────────────────────────────────────────────────────────╯
